Workbook

Sheet Batch1 calculation
D2: Unit KRW
A3: Phase 1 | C3: Paid amount for each site | D3: Total Paid amount
A4: 김한용 | B4: 드림1 | C4: 303473480 | D4: =SUM(C4:C7) -> 1210404780
B5: 드림2 | C5: 302270100
B6: 제일테크1 | C6: 302330600
B7: 제일테크2 | C7: 302330600
A8: 이홍연 | B8: 가시솔라1 (오은주) | C8: 302379000 | D8: =SUM(C8:C11) -> 1209503900
B9: 가시솔라2 (오은주) | C9: 302379000
B10: 행원햇빛 | C10: 302372950
B11: 와이제이 수산 | C11: 302372950
F13: Unit KRW
A14: Phase 2 | C14: Paid amount for each site | D14: Total Paid amount | E14: Divide for Phase 1 | F14: Amount of Divided into 5
A15: 김한용 | B15: 빛나리2 | C15: 54945000 | D15: =SUM(C15:C19) -> 211365000 | E15: 4 | F15: =D15/E15 -> 52841250
B16: 빛나리3 | C16: 11000000
B17: 빛나리4 | C17: 35530000
B18: 빛나리7 | C18: 54945000
B19: 흥산2 (김명현) | C19: 54945000
A20: 이홍연 | B20: 가시솔라1 (오은주) | C20: 54945000 | D20: =SUM(C20:C24) -> 207790000 | E20: 4 | F20: =D20/E20 -> 51947500
B21: 가시솔라2 (오은주) | C21: 7040000
B22: 행원햇빛 | C22: 54945000
B23: 와이제이 덕천 | C23: 54945000
B24: 와이제이 수산 | C24: 35915000

Sheet Week news
A1: Korea Weekly Update
A3: SN | B3: Subject | C3: Discription
A4: 1 | B4: Political Environment Update | C4: a. The Prime Minister is in power, the President is being slowly removed from his functions and the former Minister of Defense jailed. The country is likely to be preparing for elections in 2025 and few is expected from the government side in terms of new policies. This is basically a frozen environment. However, in the beginning of next year 2 major things are expected on REN side: grid release schedule and PPA price adjustment for DG.
A5: 2 | B5: KEPCO / Grid availability | C5: a. Grid release tips this week shows 1.3GW of grid release in Honam and Jeju regions announcement in January 2025. Originated plans to look after a few more ground PV from the pipeline that had secured GIA to add 3 to 5 MW to Batch 1 and 2 and completed a 21MW+ GM PV batch overall.
C6: b. More GW are expected to be released in 2026 as MoTIE extended the period of construction to frozen projects having received connection to YE 2025. Meaning many projects with limited capital may be on sale in 2025.
A7: 3 | B7: 4MWp PPA at 180won/KRW | C7: a. RWE Energy Trading reached out to Originated to get an urgent 4MWp RtB available for cPPA for one of their coal power producer clients. The expected price per MWh is said to be 180,000KRW (EUR120)
C8: b. Detailed meeting about contracting planned on Dec. 30th.
A11: Outstanding by year end
A13: SN | B13: Project | C13: What to do next
A14: 1 | B14: Ground mounted Batch 1: 8MW | C14: a. EPC contract b. pre-PPA binding contract c. KEPCO grid release date
A15: 2 | B15: Ground mounted Batch 2: 6.8MW | C15: a. APA x 6 / SPA x 4 b. LDD and taxation DD final c. 4MWp PPA with RWE @ 180KRW/kWh d. Transfer of c. 2m EUR
A16: 3 | B16: DG organic 3.633MW (+8MW tender) | C16: a. SPA completed b. Approval of 3.2MW c. Sign lease d. Transfer of 20% DEVEX to Solar City e. (Tender 8MW DG Port Kukyang Logitek)
A17: 4 | B17: Wind 37.2MW | C17: a. NBO b. LDD, Technical DD, Texation DD c. SPA/SHA/DSA d. Site extension + 37.2MW
B18: Conclusion Korea on the map with 55.7 locked in pipeline for construction in 2025 18.5MW and development 37.2MW. Next lock in campaign: + 13.8MW of DG in pipeline to be locked in by end of January 2025.

Sheet ref.Phase 1 (2)
B2: Phase 1 | L2: [단위 : 원]
B3: 구분 | C3: 지급일자 | D3: YJ NANSAN1 | E3: YJ NANSAN2 | F3: YJ GASI1 | G3: YJ GASI2 | H3: Dream1 | I3: Dream2 | J3: Jeil Tech1 | K3: Jeil Tech2 | L3: 합계 | O3: 0.1
B4: 발전용량(kw) | D4: 999.58 | E4: 999.58 | F4: 999.6 | G4: 999.6 | H4: 999.24 | I4: 999.24 | J4: 999.44 | K4: 999.44 | L4: =+SUM(E4:K4) -> 6996.14
B5: 입금액(EUR) | D5: 210448.88 | E5: 210448.88 | F5: 210453.09 | G5: 210453.09 | H5: 211354.04 | I5: 210377.3 | J5: 210419.4 | K5: 210419.4 | L5: =+SUM(E5:K5) -> 1473925.2
B6: 전체금액 | D6: =+D7/$B$7 -> 549769000 | E6: =+E7/$B$7 -> 549769000 | F6: =+F7/$B$7 -> 549780000 | G6: =+G7/$B$7 -> 549780000 | H6: =+H4*550000000/1000 -> 549582000 | I6: =+I7/$B$7 -> 549582000 | J6: =+J7/$B$7 -> 549692000 | K6: =+K7/$B$7 -> 549692000 | L6: =+L7/$B$7 -> 3850428600
B7: 0.55 | D7: 302372950 | E7: 302372950 | F7: 302379000 | G7: 302379000 | H7: 303673480 | I7: 302270100 | J7: 302330600 | K7: 302330600 | L7: =+SUM(E7:K7) -> 2117735730
B8: 추가입금액 (10%) | D8: =+D20*$O$3 -> 54976900 | E8: =+E20*$O$3 -> 54976900 | F8: =+F20*$O$3 -> 54978000 | G8: =+G20*$O$3 -> 54978000 | H8: =+H20*$O$3 -> 55213360 | I8: =+I20*$O$3 -> 54958200 | J8: =+J20*$O$3 -> 54969200 | K8: =+K20*$O$3 -> 54969200 | L8: =+SUM(E8:K8) -> 385042860
B9: 입금 금액 | D9: =+$C$18/4 -> 51947500 | E9: =+$C$18/4 -> 51947500 | F9: =+$C$18/4 -> 51947500 | G9: =+$C$18/4 -> 51947500 | H9: =+$C$17/4 -> 52841250 | I9: =+$C$17/4 -> 52841250 | J9: =+$C$17/4 -> 52841250 | K9: =+$C$17/4 -> 52841250 | L9: =+SUM(E9:K9) -> 367207500
B10: 잔금 | D10: =+D6-D7-D9 -> 195448550 | E10: =+E6-E7-E9 -> 195448550 | F10: =+F6-F7-F9 -> 195453500 | G10: =+G6-G7-G9 -> 195453500 | H10: =+H6-H7-H9 -> 193067270 | I10: =+I6-I7-I9 -> 194470650 | J10: =+J6-J7-J9 -> 194520150 | K10: =+K6-K7-K9 -> 194520150 | L10: =+L6-L7-L9 -> 1365485370
B11: 입금처 | D11: YJ SOLAR CO.LTD | E11: YJ SOLAR CO.LTD | F11: YJ SOLAR CO.LTD | G11: YJ SOLAR CO.LTD | H11: KIM HAN YONG | I11: LEE SU KYUNG | J11: KIM JUNG HEE | K11: JEIL TECH CO.LTD | L11: YJ SOLAR CO.LTD
D12: =+D9+D7 -> 354320450 | E12: =+E9+E7 -> 354320450 | F12: =+F9+F7 -> 354326500 | G12: =+G9+G7 -> 354326500 | H12: =+H9+H7 -> 356514730 | I12: =+I9+I7 -> 355111350 | J12: =+J9+J7 -> 355171850 | K12: =+K9+K7 -> 355171850
D13: 이홍연 | E13: 이홍연 | F13: 이홍연 | G13: 이홍연 | H13: 김한용 | I13: 김한용 | J13: 김한용 | K13: 김한용
B14: 0.05 | D14: =+D6*$B$14 -> 27488450 | E14: =+E6*$B$14 -> 27488450 | F14: =+F6*$B$14 -> 27489000 | G14: =+G6*$B$14 -> 27489000 | H14: =+H6*$B$14 -> 27479100 | I14: =+I6*$B$14 -> 27479100 | J14: =+J6*$B$14 -> 27484600 | K14: =+K6*$B$14 -> 27484600
B15: 0.3 | D15: =+D6*$B$15 -> 164930700 | E15: =+E6*$B$15 -> 164930700 | F15: =+F6*$B$15 -> 164934000 | G15: =+G6*$B$15 -> 164934000 | H15: =+H6*$B$15 -> 164874600 | I15: =+I6*$B$15 -> 164874600 | J15: =+J6*$B$15 -> 164907600 | K15: =+K6*$B$15 -> 164907600
D16: =+D4*550000000/1000-D6 -> 0 | E16: =+E4*550000000/1000-E6 -> 0 | F16: =+F4*550000000/1000-F6 -> 0 | G16: =+G4*550000000/1000-G6 -> 0 | H16: =+H4*550000000/1000-H6 -> 0 | I16: =+I4*550000000/1000-I6 -> 0 | J16: =+J4*550000000/1000-J6 -> 0 | K16: =+K4*550000000/1000-K6 -> 0
B17: 김한용 | C17: =+'ref.Phase 1 (2)'!C33 -> 211365000
B18: 이홍연 | C18: =+'ref.Phase 1 (2)'!C34 -> 207790000 | E18: =+C18/4 -> 51947500
B20: 전체금액 | D20: =+D7/$B$7 -> 549769000 | E20: =+E7/$B$7 -> 549769000 | F20: =+F7/$B$7 -> 549780000 | G20: =+G7/$B$7 -> 549780000 | H20: =+H7/$B$7 -> 552133600 | I20: =+I7/$B$7 -> 549582000 | J20: =+J7/$B$7 -> 549692000 | K20: =+K7/$B$7 -> 549692000
B21: 0.55 | D21: =+D20*$B$21=D7 -> TRUE | E21: =+E20*$B$21=E7 -> TRUE | F21: =+F20*$B$21=F7 -> TRUE | G21: =+G20*$B$21=G7 -> TRUE | H21: =+H20*$B$21=H7 -> TRUE | I21: =+I20*$B$21=I7 -> TRUE | J21: =+J20*$B$21=J7 -> TRUE | K21: =+K20*$B$21=K7 -> TRUE
D22: =+D7/D6 -> 0.55 | E22: =+E7/E6 -> 0.55 | F22: =+F7/F6 -> 0.55 | G22: =+G7/G6 -> 0.55 | H22: =+H7/H6 -> 0.55255354 | I22: =+I7/I6 -> 0.55 | J22: =+J7/J6 -> 0.55 | K22: =+K7/K6 -> 0.55
B25: Phase 2 | M25: [단위 : 원]
B26: 구분 | C26: 지급일자 | D26: Hangwon Hatbit PV | E26: YJ SUSAN PV | F26: Gasi Solar 1PV | G26: Gasi Solar 2PV | H26: Bitnari 2 | I26: Bitnari 3 | J26: Bitnari 4 | K26: Bitnari 7 | L26: Heungsan 2 PV | M26: YJ DUCKHUN | O26: 0.1
B27: 발전용량(kw)
B28: 입금액(EUR) | D28: 38418.78 | E28: 25112.57 | F28: 38418.78 | G28: 4922.53 | H28: 38418.78 | I28: 7691.45 | J28: 24843.37 | K28: 38418.78 | L28: 38418.78 | M28: 38418.78
B29: 0.1 | D29: 54945000 | E29: 35915000 | F29: 54945000 | G29: 7040000 | H29: 54945000 | I29: 11000000 | J29: 35530000 | K29: 54945000 | L29: 54945000 | M29: 54945000 | N29: =SUM(E29:M29) -> 364210000
B31: 입금처 | D31: YJ SOLAR CO.LTD | E31: YJ SOLAR CO.LTD | F31: OH EUN JU | G31: OH EUN JU | H31: KIM HAN YONG | I31: KIM HAN YONG | J31: KIM HAN YONG | K31: KIM HAN YONG | L31: KIM MYUNG HYUN | M31: YJ SOLAR CO.LTD
D32: 이홍연 | E32: 이홍연 | F32: 이홍연 | G32: 이홍연 | H32: 김한용 | I32: 김한용 | J32: 김한용 | K32: 김한용 | L32: 김한용 | M32: 이홍연
B33: 김한용 | C33: =+H29+I29+J29+K29+L29 -> 211365000
B34: 이홍연 | C34: =+E29+F29+G29+D29+M29 -> 207790000
C35: =+C33+C34=N29 -> FALSE

Sheet 관련 현황
B3: ▶ 작성 내용
B4: 1. Pipeline에 있는 각 Project 별 내용을 SPV별로 나눠 관리를 하기 위해 SPV별로 정리
B5: 2. 승인 받은 DG (Liquidity projection for April & May 2025) 관련 내용을 근거로 작성(지급일자)
B6: - 지급일자 4월로 승인받았으나 자금 지급이 늦어짐으로 4월을 5월로 지급하는 일정으로 작성 됨
B8: ▶ 지급일자 확인
B9: 1. 지급일자는 DEVEX 추가 지급 일정이 확정 됐을때 자료 보완 필요(계속적인 업데이트 필요)
B10: - SPV 별 자금 현황 확인 및 Broker(솔라시티, 에너지플랜 등)과 협의 후 일정 업데이트
B12: ▶Project 추가 여부
B13: 1. 그린볼트 승인 및 자금 투여 시 해당 SPV에 추가 업데이트 진행
B14: 2. 현 추가 사업자등록 완료 된 4,5,8,9,10호의 사업자도 추가 진행 가능

Sheet Summary
B2: Balance by SPV
I3: [Dated : 2025.10.04]
B4: SPV | C4: Currency | D4: =+[1]자금현황!E5 -> Balance | E4: KRW | F4: to be Paid in Oct. | G4: Requested Amount (KRW) | H4: Requested Amount (EUR) | I4: Details
B5: Bolt Taeyanggwang 1HO | C5: KRW | D5: 115042926 | E5: =+D5 -> 115042926 | I5: Please check the following.
C6: EUR | D6: 299993.87 | E6: =+D6*$E$15 -> 4.4099099e+08
C7: KRW Total | E7: =SUM(E5:E6) -> 5.5603391e+08 | F7: =+'Amount to be paid in 2025(1004)'!P52 -> 2497132990 | G7: =+F7-E7 -> 1.9410991e+09 | H7: =+G7/$E$15 -> 1320475.6
B8: POSN2HO | C8: KRW | D8: 5130070 | E8: =+D8 -> 5130070 | I8: Please check the following.
C9: EUR | D9: 0 | E9: =+D9*$E$15 -> 0
C10: KRW Total | E10: =SUM(E8:E9) -> 5130070 | F10: =+D21+D22+D23 -> 1242149643 | G10: =+F10-E10 -> 1237019573 | H10: =+G10/$E$15 -> 841509.91
B11: Total | C11: KRW | D11: =+D5 -> 115042926 | E11: =+E5 -> 115042926
C12: EUR | D12: =+D6 -> 299993.87 | E12: =+D12*$E$15 -> 4.4099099e+08
C13: KRW Total | E13: =SUM(E11:E12) -> 5.5603391e+08
D15: Exchange | E15: 1470
B18: SPV | C18: Category | D18: Requested Amount (KRW) | E18: Requested Amount (EUR) | F18: Details
B19: Bolt Taeyanggwang 1HO | C19: CAPEX | D19: =+'Amount to be paid in 2025(1004)'!P30 -> 2430003290 | E19: =+D19/$E$15 -> 1653063.5 | F19: 50% of GM_Batch1 4MWp payment is required. Scheduled payment date: 13 Oct.
C20: DEVEX | D20: =+'Amount to be paid in 2025(1004)'!P50 -> 67129700 | E20: =+D20/$E$15 -> 45666.463 | F20: Payment of the outstanding amount for GM_Batch1 4MWp is scheduled.
B21: POSN2HO | C21: CAPEX | D21: =+'Amount to be paid_POSN2HO'!D28+'Amount to be paid_POSN2HO'!D29+'Amount to be paid_POSN2HO'!D30 -> 931349470 | E21: =+D21/$E$15 -> 633571.07 | F21: Excluding the previously paid Grid Connection Fee and considering the additional requested amount, \931,349,470 (EUR 633,571.07) is requested.
C22: DEVEX | D22: =+'Amount to be paid_POSN2HO'!O22 -> 123494400 | E22: =+D22/$E$15 -> 84009.796 | F22: Funds are requested for the payment of 20% of the acquisition amount.
C23: OPEX | D23: =+'Amount to be paid_POSN2HO'!D31+'Amount to be paid_POSN2HO'!D32 -> 187305773 | E23: =+D23/$E$15 -> 127418.89 | F23: Payment of \187,305,773 (EUR 127,418.89) is requested for the Prepaid Lease Fee and OE Fee.

Sheet DEVEX Payment Status
B2: DEVEX Payment Status
B4: SPV | C4: NO | D4: Name of Project | E4: Capacity (kWp) | F4: DEVEX/MWp | G4: DEVEX Total Amount | H4: Payment ratio | I4: Total | J4: 2024 Total | K4: 2025 Total | L4: 45688 | M4: 45716 | N4: 45747 | O4: 45777 | P4: 45808 | Q4: 45838 | R4: 45869 | S4: 45900 | T4: 45930 | U4: 45961 | V4: 45991 | W4: 46022 | X4: 2026 Total | Y4: 46053 | Z4: 46081 | AA4: 46112 | AB4: 46142 | AC4: 46173 | AD4: 46203 | AE4: 46234 | AF4: 46265 | AG4: 46295 | AH4: 46326 | AI4: 46356 | AJ4: 46387
B6: Total | C6: =+C7+C8+C9+C10+C11+C12 -> 22 | E6: =+SUM(E13:E34) -> 15912.58 | G6: =+SUM(G13:G34) -> 7955636000 | H6: =+I6/G6 -> 0.61739671 | I6: =+J6+K6+X6 -> 4911783500 | J6: =+SUM(J13:J34) -> 2837860300 | K6: =+SUM(K13:K34) -> 2073923200 | L6: =+SUM(L13:L34) -> 0 | M6: =+SUM(M13:M34) -> 0 | N6: =+SUM(N13:N34) -> 0 | O6: =+SUM(O13:O34) -> 0 | P6: =+SUM(P13:P34) -> 740251200 | Q6: =+SUM(Q13:Q34) -> 0 | ... AJ6: =+SUM(AJ13:AJ34) -> 0
B7: Bolt T 1HO Total | C7: =+C26 -> 14 | E7: =+SUM(E13:E26) -> 10394.64 | G7: =+SUM(G13:G26) -> 6436728000 | H7: =+I7/G7 -> 0.55588981 | I7: =+SUM(I13:I26) -> 3578111500 | J7: =+SUM(J13:J26) -> 2837860300 | K7: =+SUM(K13:K26) -> 740251200 | L7: =+SUM(L13:L26) -> 0 | M7: =+SUM(M13:M26) -> 0 | N7: =+SUM(N13:N26) -> 0 | O7: =+SUM(O13:O26) -> 0 | P7: =+SUM(P13:P26) -> 740251200 | ... AJ7: =+SUM(AJ13:AJ26) -> 0
B8: Galsan Solar Total | C8: =+C27 -> 1 | E8: =+E27 -> 993.6 | G8: =+G27 -> 223820970 | H8: =+I8/G8 -> 1 | I8: =+I27 -> 223820970 | J8: =+J27 -> 0 | K8: =+K27 -> 223820970 | L8: =+L27 -> 0 | M8: =+M27 -> 0 | N8: =+N27 -> 0 | O8: =+O27 -> 0 | P8: =+P27 -> 0 | ... AJ8: =+AJ27 -> 0
B9: Mineuri Solar Total | C9: =+C28 -> 1 | E9: =+E28 -> 993.6 | G9: =+G28 -> 110418040 | H9: =+I9/G9 -> 1 | I9: =+I28 -> 110418040 | J9: =+J28 -> 0 | K9: =+K28 -> 110418040 | L9: =+L28 -> 0 | M9: =+M28 -> 0 | N9: =+N28 -> 0 | O9: =+O28 -> 0 | P9: =+P28 -> 0 | ... AJ9: =+AJ28 -> 0
B10: SeagolSolar Total | C10: =+C29 -> 1 | E10: =+E29 -> 993.6 | G10: =+G29 -> 108773270 | H10: =+I10/G10 -> 1 | I10: =+I29 -> 108773270 | J10: =+J29 -> 0 | K10: =+K29 -> 108773270 | L10: =+L29 -> 0 | M10: =+M29 -> 0 | N10: =+N29 -> 0 | O10: =+O29 -> 0 | P10: =+P29 -> 0 | ... AJ10: =+AJ29 -> 0
B11: Jaesan Solar Total | C11: =+C30 -> 1 | E11: =+E30 -> 993.6 | G11: =+G30 -> 458479720 | H11: =+I11/G11 -> 1 | I11: =+I30 -> 458479720 | J11: =+J30 -> 0 | K11: =+K30 -> 458479720 | L11: =+L30 -> 0 | M11: =+M30 -> 0 | N11: =+N30 -> 0 | O11: =+O30 -> 0 | P11: =+P30 -> 0 | ... AJ11: =+AJ30 -> 0
B12: POSN2HO Total | C12: 4 | E12: =+SUM(E31:E34) -> 1543.54 | G12: =+SUM(G31:G34) -> 617416000 | H12: =+I12/G12 -> 0.69998186 | I12: =+SUM(I31:I34) -> 432180000 | J12: =+SUM(J31:J34) -> 0 | K12: =+SUM(K31:K34) -> 432180000 | L12: =+SUM(L31:L34) -> 0 | M12: =+SUM(M31:M34) -> 0 | N12: =+SUM(N31:N34) -> 0 | O12: =+SUM(O31:O34) -> 0 | P12: =+SUM(P31:P34) -> 0 | ... AJ12: =+SUM(AJ31:AJ34) -> 0
B13: Bolt Taeyanggwang 1HO | C13: 1 | D13: =+'GM Batch1'!C11 -> YJ NANSAN 1 | E13: =+'GM Batch1'!D11 -> 999.58 | F13: 550000000 | G13: =+E13*F13/1000 -> 549769000 | H13: =+I13/G13 -> 0.66947518 | I13: =+J13+K13+X13 -> 368056700 | J13: =+'GM Batch1'!Q12+'GM Batch1'!X12 -> 368056700 | K13: =+SUM(L13:W13) -> 0 | X13: =+SUM(Y13:AJ13) -> 0
C14: =+C13+1 -> 2 | D14: =+'GM Batch1'!C17 -> YJ NANSAN 2 | E14: =+'GM Batch1'!D17 -> 999.58 | F14: 550000000 | G14: =+E14*F14/1000 -> 549769000 | H14: =+I14/G14 -> 0.66947518 | I14: =+J14+K14+X14 -> 368056700 | J14: =+'GM Batch1'!Q18+'GM Batch1'!X18 -> 368056700 | K14: =+SUM(L14:W14) -> 0 | X14: =+SUM(Y14:AJ14) -> 0
C15: =+C14+1 -> 3 | D15: =+'GM Batch1'!C23 -> YJ GASI 1 | E15: =+'GM Batch1'!D23 -> 999.6 | F15: 550000000 | G15: =+E15*F15/1000 -> 549780000 | H15: =+I15/G15 -> 0.66947279 | I15: =+J15+K15+X15 -> 368062750 | J15: =+'GM Batch1'!Q24+'GM Batch1'!X24 -> 368062750 | K15: =+SUM(L15:W15) -> 0 | X15: =+SUM(Y15:AJ15) -> 0
C16: =+C15+1 -> 4 | D16: =+'GM Batch1'!C29 -> YJ GASI 2 | E16: =+'GM Batch1'!D29 -> 999.6 | F16: 550000000 | G16: =+E16*F16/1000 -> 549780000 | H16: =+I16/G16 -> 0.66947279 | I16: =+J16+K16+X16 -> 368062750 | J16: =+'GM Batch1'!Q30+'GM Batch1'!X30 -> 368062750 | K16: =+SUM(L16:W16) -> 0 | X16: =+SUM(Y16:AJ16) -> 0
C17: =+C16+1 -> 5 | D17: =+'GM Batch1'!C35 -> Dream 1 | E17: =+'GM Batch1'!D35 -> 999.24 | F17: 550000000 | G17: =+E17*F17/1000 -> 549582000 | H17: =+I17/G17 -> 0.62115408 | I17: =+J17+K17+X17 -> 341375100 | J17: =+'GM Batch1'!Q36+'GM Batch1'!X36 -> 341375100 | K17: =+SUM(L17:W17) -> 0 | X17: =+SUM(Y17:AJ17) -> 0
C18: =+C17+1 -> 6 | D18: =+'GM Batch1'!C41 -> Dream 2 | E18: =+'GM Batch1'!D41 -> 999.24 | F18: 550000000 | G18: =+E18*F18/1000 -> 549582000 | H18: =+I18/G18 -> 0.62115408 | I18: =+J18+K18+X18 -> 341375100 | J18: =+'GM Batch1'!Q42+'GM Batch1'!X42 -> 341375100 | K18: =+SUM(L18:W18) -> 0 | X18: =+SUM(Y18:AJ18) -> 0
C19: =+C18+1 -> 7 | D19: =+'GM Batch1'!C47 -> JEIL TECH 1 | E19: =+'GM Batch1'!D47 -> 999.44 | F19: 550000000 | G19: =+E19*F19/1000 -> 549692000 | H19: =+I19/G19 -> 0.62113984 | I19: =+J19+K19+X19 -> 341435600 | J19: =+'GM Batch1'!Q48+'GM Batch1'!X48 -> 341435600 | K19: =+SUM(L19:W19) -> 0 | X19: =+SUM(Y19:AJ19) -> 0
C20: =+C19+1 -> 8 | D20: =+'GM Batch1'!C53 -> JEIL TECH 2 | E20: =+'GM Batch1'!D53 -> 999.44 | F20: 550000000 | G20: =+E20*F20/1000 -> 549692000 | H20: =+I20/G20 -> 0.62113984 | I20: =+J20+K20+X20 -> 341435600 | J20: =+'GM Batch1'!Q54+'GM Batch1'!X54 -> 341435600 | K20: =+SUM(L20:W20) -> 0 | X20: =+SUM(Y20:AJ20) -> 0
C21: =+C20+1 -> 9 | D21: =+'GM Batch2-APA'!C11 -> Jangchon 1 (APA) | E21: =+'GM Batch2-APA'!D11 -> 551.04 | F21: 850000000 | G21: =+E21*F21/1000 -> 468384000 | H21: =+I21/G21 -> 0.55467821 | I21: =+J21+K21+X21 -> 259802400 | K21: =+SUM(L21:W21) -> 259802400 | P21: =+'GM Batch2-APA'!Q12+'GM Batch2-APA'!Q13+'GM Batch2-APA'!Q14 -> 259802400 | X21: =+SUM(Y21:AJ21) -> 0
C22: =+C21+1 -> 10 | D22: =+'GM Batch2-APA'!C17 -> Soltop Masan 1 (APA) | E22: =+'GM Batch2-APA'!D17 -> 399.04 | F22: 850000000 | G22: =+E22*F22/1000 -> 339184000 | H22: =+I22/G22 -> 0.30588235 | I22: =+J22+K22+X22 -> 103750400 | K22: =+SUM(L22:W22) -> 103750400 | P22: =+'GM Batch2-APA'!Q18+'GM Batch2-APA'!Q19+'GM Batch2-APA'!Q20 -> 103750400 | X22: =+SUM(Y22:AJ22) -> 0
C23: =+C22+1 -> 11 | D23: =+'GM Batch2-APA'!C23 -> Hanil Mugok 15 (APA) | E23: =+'GM Batch2-APA'!D23 -> 499.96 | F23: 850000000 | G23: =+E23*F23/1000 -> 424966000 | H23: =+I23/G23 -> 0.30588235 | I23: =+J23+K23+X23 -> 129989600 | K23: =+SUM(L23:W23) -> 129989600 | P23: =+'GM Batch2-APA'!Q24+'GM Batch2-APA'!Q25+'GM Batch2-APA'!Q26 -> 129989600 | X23: =+SUM(Y23:AJ23) -> 0
C24: =+C23+1 -> 12 | D24: =+'GM Batch2-APA'!C29 -> Hanil Jigyeong 1 (APA) | E24: =+'GM Batch2-APA'!D29 -> 499.96 | F24: 850000000 | G24: =+E24*F24/1000 -> 424966000 | H24: =+I24/G24 -> 0.30588235 | I24: =+J24+K24+X24 -> 129989600 | K24: =+SUM(L24:W24) -> 129989600 | P24: =+'GM Batch2-APA'!Q30+'GM Batch2-APA'!Q31+'GM Batch2-APA'!Q32 -> 129989600 | X24: =+SUM(Y24:AJ24) -> 0
C25: =+C24+1 -> 13 | D25: =+'GM Batch2-APA'!C35 -> Hanil Jigyeong 2 (APA) | E25: =+'GM Batch2-APA'!D35 -> 149.64 | F25: 850000000 | G25: =+E25*F25/1000 -> 127194000 | H25: =+I25/G25 -> 0.30588235 | I25: =+J25+K25+X25 -> 38906400 | K25: =+SUM(L25:W25) -> 38906400 | P25: =+'GM Batch2-APA'!Q36+'GM Batch2-APA'!Q37+'GM Batch2-APA'!Q38 -> 38906400 | X25: =+SUM(Y25:AJ25) -> 0
C26: =+C25+1 -> 14 | D26: =+'GM Batch2-APA'!C41 -> Ho Duck4 (APA) | E26: =+'GM Batch2-APA'!D41 -> 299.28 | F26: 850000000 | G26: =+E26*F26/1000 -> 254388000 | H26: =+I26/G26 -> 0.30588235 | I26: =+J26+K26+X26 -> 77812800 | K26: =+SUM(L26:W26) -> 77812800 | P26: =+'GM Batch2-APA'!Q42+'GM Batch2-APA'!Q43+'GM Batch2-APA'!Q44 -> 77812800 | X26: =+SUM(Y26:AJ26) -> 0
B27: Galsan Solar | C27: 1 | D27: =+'GM Batch2-SPA'!C11 -> Galsan (SPA) | E27: =+'GM Batch2-SPA'!D11 -> 993.6 | F27: =+G27/E27*1000 -> 2.2526265e+08 | G27: 223820970 | H27: =+I27/G27 -> 1 | I27: =+J27+K27+X27 -> 223820970 | K27: =+SUM(L27:W27) -> 223820970 | R27: =+'GM Batch2-SPA'!Q12 -> 223820970 | X27: =+SUM(Y27:AJ27) -> 0
B28: Mineuri Solar | C28: 1 | D28: =+'GM Batch2-SPA'!C17 -> Mineuri (SPA) | E28: =+'GM Batch2-SPA'!D17 -> 993.6 | F28: =+G28/E28*1000 -> 1.1112927e+08 | G28: 110418040 | H28: =+I28/G28 -> 1 | I28: =+J28+K28+X28 -> 110418040 | K28: =+SUM(L28:W28) -> 110418040 | R28: =+'GM Batch2-SPA'!Q18 -> 110418040 | X28: =+SUM(Y28:AJ28) -> 0
B29: SeagolSolar | C29: 1 | D29: =+'GM Batch2-SPA'!C23 -> Seagol(SPA) | E29: =+'GM Batch2-SPA'!D23 -> 993.6 | F29: =+G29/E29*1000 -> 1.094739e+08 | G29: 108773270 | H29: =+I29/G29 -> 1 | I29: =+J29+K29+X29 -> 108773270 | K29: =+SUM(L29:W29) -> 108773270 | R29: =+'GM Batch2-SPA'!Q24 -> 108773270 | X29: =+SUM(Y29:AJ29) -> 0
B30: Jaesan Solar | C30: 1 | D30: =+'GM Batch2-SPA'!C29 -> Jaesan (SPA) | E30: =+'GM Batch2-SPA'!D29 -> 993.6 | F30: =+G30/E30*1000 -> 4.6143289e+08 | G30: 458479720 | H30: =+I30/G30 -> 1 | I30: =+J30+K30+X30 -> 458479720 | K30: =+SUM(L30:W30) -> 458479720 | R30: =+'GM Batch2-SPA'!Q30 -> 458479720 | X30: =+SUM(Y30:AJ30) -> 0
B31: POSN2HO | C31: 1 | D31: =+'DG M&A-SPA_POSN'!C11 -> POS-1 | E31: =+'DG M&A-SPA_POSN'!D11 -> 340.8 | F31: 400000000 | G31: =+E31*F31/1000 -> 136320000 | H31: =+I31/G31 -> 0.74535211 | I31: =+J31+K31+X31 -> 101606400 | K31: =+SUM(L31:W31) -> 101606400 | R31: =+'DG M&A-SPA_POSN'!Q12 -> 101606400 | X31: =+SUM(Y31:AJ31) -> 0
C32: =+C31+1 -> 2 | D32: =+'DG M&A-SPA_POSN'!C17 -> POS-3 | E32: =+'DG M&A-SPA_POSN'!D17 -> 144.84 | F32: 400000000 | G32: =+E32*F32/1000 -> 57936000 | H32: =+I32/G32 -> 0.68202154 | I32: =+J32+K32+X32 -> 39513600 | K32: =+SUM(L32:W32) -> 39513600 | R32: =+'DG M&A-SPA_POSN'!Q18 -> 39513600 | X32: =+SUM(Y32:AJ32) -> 0
C33: =+C32+1 -> 3 | D33: =+'DG M&A-SPA_POSN'!C23 -> POS-4 | E33: =+'DG M&A-SPA_POSN'!D23 -> 807.98 | F33: 400000000 | G33: =+E33*F33/1000 -> 323192000 | H33: =+I33/G33 -> 0.68498601 | I33: =+J33+K33+X33 -> 221382000 | K33: =+SUM(L33:W33) -> 221382000 | R33: =+'DG M&A-SPA_POSN'!Q24 -> 221382000 | X33: =+SUM(Y33:AJ33) -> 0
C34: =+C33+1 -> 4 | D34: =+'DG M&A-SPA_POSN'!C29 -> POS-8 | E34: =+'DG M&A-SPA_POSN'!D29 -> 249.92 | F34: 400000000 | G34: =+E34*F34/1000 -> 99968000 | H34: =+I34/G34 -> 0.69700304 | I34: =+J34+K34+X34 -> 69678000 | K34: =+SUM(L34:W34) -> 69678000 | R34: =+'DG M&A-SPA_POSN'!Q30 -> 69678000 | X34: =+SUM(Y34:AJ34) -> 0

Sheet Amount to be paid in 2025(1004)
B2: SPV Name | D2: Bolt Taeyanggwang 1HO
B3: Business License Number | D3: 388-86-03459
B4: Corporate Registry Number | D4: 110111-9077515
B5: SPV Address | D5: #214, 42, Eonju-ro 147-gil, Gangnam-gu, Seoul, Korea | P5: =+P11+P12 -> 1214989490
B6: Project Tech. | D6: GM_Batch1,2, DG_M&A | P6: =+P5/1470 -> 826523.46
B7: Bank & Bank account Number | D7: KB Bank : 096368-11-010020
Y8: [Unit : KRW, EUR]
B9: SPV | C9: Name of Project | D9: CAPEX per kWp | E9: DEVEX per kWp | F9: Capacity (kWp) | G9: Total amount to be settled | H9: Amount scheduled to be paid in Jul. to Sep. | I9: 전체 지급예정 | J9: Total | K9: Paid (By Sep. 30, 2025) | L9: Balance on Sep. 30, 2025 | M9: Required funds for Oct. | N9: Amount scheduled to be paid in Oct. | O9: Oct. | Q9: Amount scheduled to be paid in Nov. | R9: Nov. | T9: Dec. | V9: Jan. 2026 | X9: After Jan.2026 | AA9: Review
O10: Date | P10: Payment | R10: Date | S10: Payment | T10: Date | U10: Payment | V10: Date | W10: Payment
B11: Bolt Taeyanggwang 1HO | C11: YJ NANSAN 1 | D11: =1050000+$D$64/1000 -> 1077500 | F11: 999.58 | G11: =D11*F11*1.1/1470 -> 805953.87 | H11: =+P11+S11 -> 896123470 | I11: =+F11*D11*1.1 -> 1184752195 | J11: =+K11+P11+S11+U11+Y11+W11 -> 1184752195 | K11: =+'GM Batch1'!AE11 -> 231000000 | N11: =+P11 -> 607494745 | O11: =+'GM Batch1'!AO11 -> 45950 | P11: =+'GM Batch1'!AR11 -> 607494745 | Q11: =+S11 -> 288628725 | R11: =+'GM Batch1'!BC11 -> 45991 | S11: =+'GM Batch1'!BF11 -> 288628725 | T11: =+'GM Batch1'!BJ11 -> 46022 | U11: =+'GM Batch1'!BM11+'GM Batch1'!AF11 -> 57628725 | AA11: =+I11=J11 -> 1
C12: YJ NANSAN 2 | D12: =1050000+$D$64/1000 -> 1077500 | F12: 999.58 | G12: =D12*F12*1.1/1470 -> 805953.87 | H12: =+P12+S12 -> 896123470 | I12: =+F12*D12*1.1 -> 1184752195 | J12: =+K12+P12+S12+U12+Y12+W12 -> 1184752195 | K12: =+'GM Batch1'!AE17 -> 231000000 | N12: =+P12 -> 607494745 | O12: =+'GM Batch1'!AO17 -> 45950 | P12: =+'GM Batch1'!AR17 -> 607494745 | Q12: =+S12 -> 288628725 | R12: =+'GM Batch1'!BC17 -> 45991 | S12: =+'GM Batch1'!BF17 -> 288628725 | T12: =+'GM Batch1'!BJ17 -> 46022 | U12: =+'GM Batch1'!BM17+'GM Batch1'!AF17 -> 57628725 | AA12: =+I12=J12 -> 1
C13: YJ GASI 1 | D13: =1050000+$D$64/1000 -> 1077500 | F13: 999.6 | G13: =D13*F13*1.1/1470 -> 805970 | H13: =+P13+S13 -> 896141400 | I13: =+F13*D13*1.1 -> 1184775900 | J13: =+K13+P13+S13+U13+Y13+W13 -> 1184775900 | K13: =+'GM Batch1'!AE23 -> 231000000 | N13: =+P13 -> 607506900 | O13: =+'GM Batch1'!AO23 -> 45950 | P13: =+'GM Batch1'!AR23 -> 607506900 | Q13: =+S13 -> 288634500 | R13: =+'GM Batch1'!BC23 -> 45991 | S13: =+'GM Batch1'!BF23 -> 288634500 | T13: =+'GM Batch1'!BJ23 -> 46022 | U13: =+'GM Batch1'!BM23+'GM Batch1'!AF23 -> 57634500 | AA13: =+I13=J13 -> TRUE
C14: YJ GASI 2 | D14: =1050000+$D$64/1000 -> 1077500 | F14: 999.6 | G14: =D14*F14*1.1/1470 -> 805970 | H14: =+P14+S14 -> 896141400 | I14: =+F14*D14*1.1 -> 1184775900 | J14: =+K14+P14+S14+U14+Y14+W14 -> 1184775900 | K14: =+'GM Batch1'!AE29 -> 231000000 | N14: =+P14 -> 607506900 | O14: =+'GM Batch1'!AO29 -> 45950 | P14: =+'GM Batch1'!AR29 -> 607506900 | Q14: =+S14 -> 288634500 | R14: =+'GM Batch1'!BC29 -> 45991 | S14: =+'GM Batch1'!BF29 -> 288634500 | T14: =+'GM Batch1'!BJ29 -> 46022 | U14: =+'GM Batch1'!BM29+'GM Batch1'!AF29 -> 57634500 | AA14: =+I14=J14 -> TRUE
C15: Dream 1 | D15: =1050000+$D$64/1000 -> 1077500 | F15: 999.24 | G15: =D15*F15*1.1/1470 -> 805679.73 | H15: =+P15+S15 -> 0 | I15: =+F15*D15*1.1 -> 1184349210 | J15: =+K15+P15+S15+U15+Y15+W15 -> 1184349210 | K15: 0 | N15: =+P15 -> 0 | Q15: =+S15 -> 0 | V15: =+'GM Batch1'!AA35 -> 46052 | W15: =+'GM Batch1'!AD35 -> 230824440 | Y15: =+'GM Batch1'!I35-'GM Batch1'!AD35 -> 953524770 | AA15: =+I15=J15 -> TRUE
C16: Dream 2 | D16: =1050000+$D$64/1000 -> 1077500 | F16: 999.24 | G16: =D16*F16*1.1/1470 -> 805679.73 | H16: =+P16+S16 -> 0 | I16: =+F16*D16*1.1 -> 1184349210 | J16: =+K16+P16+S16+U16+Y16+W16 -> 1184349210 | K16: 0 | N16: =+P16 -> 0 | Q16: =+S16 -> 0 | V16: =+'GM Batch1'!AA41 -> 46052 | W16: =+'GM Batch1'!AD41 -> 230824440 | Y16: =+'GM Batch1'!I41-'GM Batch1'!AD41 -> 953524770 | AA16: =+I16=J16 -> TRUE
C17: JEIL TECH 1 | D17: =1050000+$D$64/1000 -> 1077500 | F17: 999.44 | G17: =D17*F17*1.1/1470 -> 805840.99 | H17: =+P17+S17 -> 0 | I17: =+F17*D17*1.1 -> 1184586260 | J17: =+K17+P17+S17+U17+Y17+W17 -> 1184586260 | K17: 0 | N17: =+P17 -> 0 | Q17: =+S17 -> 0 | V17: =+'GM Batch1'!AA47 -> 46052 | W17: =+'GM Batch1'!AD47 -> 230870640 | Y17: =+'GM Batch1'!I47-'GM Batch1'!AD47 -> 953715620 | AA17: =+I17=J17 -> TRUE
C18: JEIL TECH 2 | D18: =1050000+$D$64/1000 -> 1077500 | F18: 999.44 | G18: =D18*F18*1.1/1470 -> 805840.99 | H18: =+P18+S18 -> 0 | I18: =+F18*D18*1.1 -> 1184586260 | J18: =+K18+P18+S18+U18+Y18+W18 -> 1184586260 | K18: 0 | N18: =+P18 -> 0 | Q18: =+S18 -> 0 | V18: =+'GM Batch1'!AA53 -> 46052 | W18: =+'GM Batch1'!AD53 -> 230870640 | Y18: =+'GM Batch1'!I53-'GM Batch1'!AD53 -> 953715620 | AA18: =+I18=J18 -> 1
C19: Jangchon 1 (APA) | D19: =1050000+$D$64/1000 -> 1077500 | F19: 999.24 | G19: =D19*F19*1.1/1470 -> 805679.73 | H19: =+P19+S19 -> 0 | I19: =+F19*D19*1.1 -> 1184349210 | J19: =+K19+P19+S19+U19+Y19+W19 -> 0 | N19: =+P19 -> 0 | Q19: =+S19 -> 0 | AA19: =+I19=J19 -> 0
C20: Soltop Masan 1 (APA) | D20: =1050000+$D$64/1000 -> 1077500 | F20: 399.04 | G20: =D20*F20*1.1/1470 -> 321742.97 | H20: =+P20+S20 -> 0 | I20: =+F20*D20*1.1 -> 472962160 | J20: =+K20+P20+S20+U20+Y20+W20 -> 0 | N20: =+P20 -> 0 | Q20: =+S20 -> 0 | AA20: =+I20=J20 -> 0
C21: Hanil Mugok 15 (APA) | D21: =1050000+$D$64/1000 -> 1077500 | F21: 499.96 | G21: =D21*F21*1.1/1470 -> 403114.01 | H21: =+P21+S21 -> 0 | I21: =+F21*D21*1.1 -> 592577590 | J21: =+K21+P21+S21+U21+Y21+W21 -> 0 | N21: =+P21 -> 0 | Q21: =+S21 -> 0 | AA21: =+I21=J21 -> 0
C22: Hanil Jigyeong 1 (APA) | D22: =1050000+$D$64/1000 -> 1077500 | F22: 499.96 | G22: =D22*F22*1.1/1470 -> 403114.01 | H22: =+P22+S22 -> 0 | I22: =+F22*D22*1.1 -> 592577590 | J22: =+K22+P22+S22+U22+Y22+W22 -> 0 | N22: =+P22 -> 0 | Q22: =+S22 -> 0
C23: Hanil Jigyeong 2 (APA) | D23: =1050000+$D$64/1000 -> 1077500 | F23: 149.64 | G23: =D23*F23*1.1/1470 -> 120653.61 | H23: =+P23+S23 -> 0 | I23: =+F23*D23*1.1 -> 177360810 | J23: =+K23+P23+S23+U23+Y23+W23 -> 0 | N23: =+P23 -> 0 | Q23: =+S23 -> 0
C24: Ho Duck4 (APA) | D24: =1050000+$D$64/1000 -> 1077500 | F24: 299.28 | G24: =D24*F24*1.1/1470 -> 241307.22 | H24: =+P24+S24 -> 0 | I24: =+F24*D24*1.1 -> 354721620 | J24: =+K24+P24+S24+U24+Y24+W24 -> 0 | N24: =+P24 -> 0 | Q24: =+S24 -> 0
C25: Galsan (SPA) | D25: =1050000+$D$64/1000 -> 1077500 | F25: 993.6 | G25: =D25*F25*1.1/1470 -> 801132.24 | H25: =+P25+S25 -> 0 | I25: =+F25*D25*1.1 -> 1177664400 | J25: =+K25+P25+S25+U25+Y25+W25 -> 0 | N25: =+P25 -> 0 | Q25: =+S25 -> 0
C26: Mineuri (SPA) | D26: =1050000+$D$64/1000 -> 1077500 | F26: 993.6 | G26: =D26*F26*1.1/1470 -> 801132.24 | H26: =+P26+S26 -> 0 | I26: =+F26*D26*1.1 -> 1177664400 | J26: =+K26+P26+S26+U26+Y26+W26 -> 0 | N26: =+P26 -> 0 | Q26: =+S26 -> 0
C27: Saegol (SPA) | D27: =1050000+$D$64/1000 -> 1077500 | F27: 993.6 | G27: =D27*F27*1.1/1470 -> 801132.24 | H27: =+P27+S27 -> 0 | I27: =+F27*D27*1.1 -> 1177664400 | J27: =+K27+P27+S27+U27+Y27+W27 -> 0 | N27: =+P27 -> 0 | Q27: =+S27 -> 0
C28: Jaesan (SPA) | D28: =1050000+$D$64/1000 -> 1077500 | F28: 993.6 | G28: =D28*F28*1.1/1470 -> 801132.24 | H28: =+P28+S28 -> 0 | I28: =+F28*D28*1.1 -> 1177664400 | J28: =+K28+P28+S28+U28+Y28+W28 -> 0 | N28: =+P28 -> 0 | Q28: =+S28 -> 0 | AA28: =+I28=J28 -> 0
C29: CAPEX Total | F29: =+SUM(F11:F28) -> 14817.24 | G29: =SUM(G11:G28) -> 11947030 | H29: =H30/1470 -> 2438455.6 | I29: =I30/1470 -> 6446889.2 | J29: =J30/1470 -> 6446889.2 | K29: =K30/1470 -> 628571.43 | N29: =N30/1470 -> 1653063.5 | P29: =P30/1470 -> 1653063.5 | Q29: =Q30/1470 -> 785392.14 | S29: =S30/1470 -> 785392.14 | U29: =U30/1470 -> 156820.71 | W29: =W30/1470 -> 628156.57 | Y29: =Y30/1470 -> 2594884.9
H30: =+SUM(H11:H18) -> 3584529740 | I30: =+SUM(I11:I18) -> 9476927130 | J30: =+SUM(J11:J18) -> 9476927130 | K30: =+SUM(K11:K18) -> 924000000 | N30: =+SUM(N11:N18) -> 2430003290 | O30: =+SUM(O11:O18) -> 183800 | P30: =+SUM(P11:P18) -> 2430003290 | Q30: =+SUM(Q11:Q18) -> 1154526450 | R30: =+SUM(R11:R18) -> 183964 | S30: =+SUM(S11:S18) -> 1154526450 | T30: =+SUM(T11:T18) -> 184088 | U30: =+SUM(U11:U18) -> 230526450 | ... Y30: =+SUM(Y11:Y18) -> 3814480780
C31: YJ NANSAN 1 | E31: 550000 | F31: 999.58 | G31: =E31*F31*1.1/1470 -> 411391.77 | H31: =+P31+S31 -> 16781600 | I31: =+E31*F31 -> 549769000 | J31: =+K31+P31+S31+U31+Y31+W31 -> 549769000 | K31: =+'GM Batch1'!K12 -> 368056700 | N31: =+P31 -> 16781600 | O31: =+'GM Batch1'!AA12 -> 45950 | P31: =+'GM Batch1'!AD12 -> 16781600 | Q31: =+S31 -> 0 | T31: =+'GM Batch1'!BJ12 -> 46022 | U31: =+'GM Batch1'!BM12 -> 164930700 | AA31: =+I31=J31 -> TRUE
C32: YJ NANSAN 2 | E32: 550000 | F32: 999.58 | G32: =E32*F32*1.1/1470 -> 411391.77 | H32: =+P32+S32 -> 16781600 | I32: =+E32*F32 -> 549769000 | J32: =+K32+P32+S32+U32+Y32+W32 -> 549769000 | K32: =+'GM Batch1'!K18 -> 368056700 | N32: =+P32 -> 16781600 | O32: =+'GM Batch1'!AA18 -> 45950 | P32: =+'GM Batch1'!AD18 -> 16781600 | Q32: =+S32 -> 0 | T32: =+'GM Batch1'!BJ18 -> 46022 | U32: =+'GM Batch1'!BM18 -> 164930700 | AA32: =+I32=J32 -> 1
C33: YJ GASI 1 | E33: 550000 | F33: 999.6 | G33: =E33*F33*1.1/1470 -> 411400 | H33: =+P33+S33 -> 16783250 | I33: =+E33*F33 -> 549780000 | J33: =+K33+P33+S33+U33+Y33+W33 -> 549780000 | K33: =+'GM Batch1'!K24 -> 368062750 | N33: =+P33 -> 16783250 | O33: =+'GM Batch1'!AA24 -> 45950 | P33: =+'GM Batch1'!AD24 -> 16783250 | Q33: =+S33 -> 0 | T33: =+'GM Batch1'!BJ24 -> 46022 | U33: =+'GM Batch1'!BM24 -> 164934000 | AA33: =+I33=J33 -> TRUE
C34: YJ GASI 2 | E34: 550000 | F34: 999.6 | G34: =E34*F34*1.1/1470 -> 411400 | H34: =+P34+S34 -> 16783250 | I34: =+E34*F34 -> 549780000 | J34: =+K34+P34+S34+U34+Y34+W34 -> 549780000 | K34: =+'GM Batch1'!K30 -> 368062750 | N34: =+P34 -> 16783250 | O34: =+'GM Batch1'!AA30 -> 45950 | P34: =+'GM Batch1'!AD30 -> 16783250 | Q34: =+S34 -> 0 | T34: =+'GM Batch1'!BJ30 -> 46022 | U34: =+'GM Batch1'!BM30 -> 164934000 | AA34: =+I34=J34 -> TRUE
C35: Dream 1 | E35: 550000 | F35: 999.24 | G35: =E35*F35*1.1/1470 -> 411251.84 | H35: =+P35+S35 -> 0 | I35: =+E35*F35 -> 549582000 | J35: =+K35+P35+S35+U35+Y35+W35 -> 549582000 | K35: =+'GM Batch1'!K36 -> 341375100 | N35: =+P35 -> 0 | Q35: =+S35 -> 0 | T35: =+'GM Batch1'!AA36 -> 46022 | U35: =+'GM Batch1'!AD36 -> 43332300 | Y35: =+'GM Batch1'!BM36 -> 164874600 | AA35: =+I35=J35 -> TRUE
C36: Dream 2 | E36: 550000 | F36: 999.24 | G36: =E36*F36*1.1/1470 -> 411251.84 | H36: =+P36+S36 -> 0 | I36: =+E36*F36 -> 549582000 | J36: =+K36+P36+S36+U36+Y36+W36 -> 549582000 | K36: =+'GM Batch1'!K42 -> 341375100 | N36: =+P36 -> 0 | Q36: =+S36 -> 0 | T36: =+'GM Batch1'!AA42 -> 46022 | U36: =+'GM Batch1'!AD42 -> 43332300 | Y36: =+'GM Batch1'!BM42 -> 164874600 | AA36: =+I36=J36 -> TRUE
C37: JEIL TECH 1 | E37: 550000 | F37: 999.44 | G37: =E37*F37*1.1/1470 -> 411334.15 | H37: =+P37+S37 -> 0 | I37: =+E37*F37 -> 549692000 | J37: =+K37+P37+S37+U37+Y37+W37 -> 549692000 | K37: =+'GM Batch1'!K48 -> 341435600 | N37: =+P37 -> 0 | Q37: =+S37 -> 0 | T37: =+'GM Batch1'!AA48 -> 46022 | U37: =+'GM Batch1'!AD48 -> 43348800 | Y37: =+'GM Batch1'!BM48 -> 164907600 | AA37: =+I37=J37 -> TRUE
C38: JEIL TECH 2 | E38: 550000 | F38: 999.44 | G38: =E38*F38*1.1/1470 -> 411334.15 | H38: =+P38+S38 -> 0 | I38: =+E38*F38 -> 549692000 | J38: =+K38+P38+S38+U38+Y38+W38 -> 549692000 | K38: =+'GM Batch1'!K54 -> 341435600 | N38: =+P38 -> 0 | Q38: =+S38 -> 0 | T38: =+'GM Batch1'!AA54 -> 46022 | U38: =+'GM Batch1'!AD54 -> 43348800 | Y38: =+'GM Batch1'!BM54 -> 164907600 | AA38: =+I38=J38 -> 1
C39: Jangchon 1 (APA) | E39: 850000 | F39: 999.24 | G39: =E39*F39*1.1/1470 -> 635571.02 | H39: =+P39+S39 -> 0 | I39: =+E39*F39 -> 849354000 | J39: =+K39+P39+S39+U39+Y39+W39 -> 0 | N39: =+P39 -> 0 | Q39: =+S39 -> 0 | AA39: =+I39=J39 -> 0
C40: Soltop Masan 1 (APA) | E40: 850000 | F40: 399.04 | G40: =E40*F40*1.1/1470 -> 253811.16 | H40: =+P40+S40 -> 0 | I40: =+E40*F40 -> 339184000 | J40: =+K40+P40+S40+U40+Y40+W40 -> 0 | N40: =+P40 -> 0 | Q40: =+S40 -> 0 | AA40: =+I40=J40 -> 0
C41: Hanil Mugok 15 (APA) | E41: 850000 | F41: 499.96 | G41: =E41*F41*1.1/1470 -> 318001.77 | H41: =+P41+S41 -> 0 | I41: =+E41*F41 -> 424966000 | J41: =+K41+P41+S41+U41+Y41+W41 -> 0 | N41: =+P41 -> 0 | Q41: =+S41 -> 0 | AA41: =+I41=J41 -> 0
...

Sheet Amount to be paid_POSN2HO
B2: SPV Name | D2: POSN2HO
B3: Business License Number | D3: 609-87-03315
B4: Corporate Registry Number | D4: 110111-8843256
B5: SPV Address | D5: #228, 42, Eonju-ro 147-gil, Gangnam-gu, Seoul, Korea
B6: Project Tech. | D6: DG_M&A
B7: Bank & Bank account Number | D7: KB Bank : 096301-04-106357
V8: [Unit : KRW, EUR / 1EUR=1,470KRW]
B9: SPV | C9: Batch | D9: Name of Project | E9: CAPEX per kWp | F9: DEVEX per kWp | G9: Capacity (kWp) | H9: Total amount to be settled | I9: Total | J9: Paid (By Sep. 30, 2025) | K9: Balance on Sep. 30, 2025 | L9: Required funds for Oct. | M9: Amount scheduled to be paid in Oct. | N9: Oct. | P9: Amount scheduled to be paid in Oct. to After Oct. | Q9: Nov. | S9: Dec. | U9: Jan. 2026 | X9: Review
N10: Date | O10: Payment | Q10: Date | R10: Payment | S10: Date | T10: Payment
B11: POSN2HO | C11: DG_M&A | D11: POS-1 | E11: 1100000 | G11: =+'DG M&A-SPA_POSN'!D11 -> 340.8 | H11: =+E11*G11*1.1/1470 -> 280522.45 | I11: =+J11+M11+P11 -> 206184000 | M11: =+O11 -> 206184000 | N11: =+'DG M&A-SPA_POSN'!AA11 -> 45960 | O11: =+'DG M&A-SPA_POSN'!AD11 -> 206184000 | P11: =+R11 -> 0 | V11: =+'DG M&A-SPA_POSN'!BM11 -> 206184000 | X11: =+J11+M11+P11+V11=G11*E11*1.1 -> 1
D12: POS-3 | E12: 1100000 | G12: =+'DG M&A-SPA_POSN'!D17 -> 144.84 | H12: =+E12*G12*1.1/1470 -> 119222.04 | I12: =+J12+M12+P12 -> 87628200 | M12: =+O12 -> 87628200 | N12: =+'DG M&A-SPA_POSN'!AA17 -> 45960 | O12: =+'DG M&A-SPA_POSN'!AD17 -> 87628200 | P12: =+R12 -> 0 | V12: =+'DG M&A-SPA_POSN'!BM17 -> 87628200 | X12: =+J12+M12+P12+V12=G12*E12*1.1 -> 1
D13: POS-4 | E13: 1100000 | G13: =+'DG M&A-SPA_POSN'!D23 -> 807.98 | H13: =+E13*G13*1.1/1470 -> 665071.97 | I13: =+J13+M13+P13 -> 488827900 | M13: =+O13 -> 488827900 | N13: =+'DG M&A-SPA_POSN'!AA23 -> 45960 | O13: =+'DG M&A-SPA_POSN'!AD23 -> 488827900 | P13: =+R13 -> 0 | V13: =+'DG M&A-SPA_POSN'!BM23 -> 488827900 | X13: =+J13+M13+P13+V13=G13*E13*1.1 -> 1
D14: POS-8 | E14: 1100000 | G14: =+'DG M&A-SPA_POSN'!D29 -> 249.92 | H14: =+E14*G14*1.1/1470 -> 205716.46 | I14: =+J14+M14+P14 -> 151201600 | M14: =+O14 -> 151201600 | N14: =+'DG M&A-SPA_POSN'!AA29 -> 45960 | O14: =+'DG M&A-SPA_POSN'!AD29 -> 151201600 | P14: =+R14 -> 0 | V14: =+'DG M&A-SPA_POSN'!BM29 -> 151201600 | X14: =+J14+M14+P14+V14=G14*E14*1.1 -> 1
D15: Total | G15: =SUM(G11:G14) -> 1543.54 | H15: =SUM(H11:H14) -> 1270532.9 | I15: =I16/1470 -> 635266.46 | J15: =J16/1470 -> 0 | M15: =M16/1470 -> 635266.46 | O15: =O16/1470 -> 635266.46 | P15: =P16/1470 -> 0 | R15: =R16/1470 -> 0 | T15: =T16/1470 -> 0 | V15: =V16/1470 -> 635266.46
I16: =+SUM(I11:I14) -> 933841700 | J16: =+SUM(J11:J14) -> 0 | M16: =+SUM(M11:M14) -> 933841700 | O16: =+SUM(O11:O14) -> 933841700 | P16: =+SUM(P11:P14) -> 0 | R16: =+SUM(R11:R14) -> 0 | T16: =+SUM(T11:T14) -> 0 | V16: =+SUM(V11:V14) -> 933841700
C17: DG_M&A | D17: POS-1 | F17: 400000 | G17: =+'DG M&A-SPA_POSN'!D11 -> 340.8 | H17: =+F17*G17/1470 -> 92734.694 | I17: =+J17+M17+P17 -> 122688000 | J17: =+'DG M&A-SPA_POSN'!Q12 -> 101606400 | M17: =+O17 -> 21081600 | N17: =+'DG M&A-SPA_POSN'!AA17 -> 45960 | O17: =+'DG M&A-SPA_POSN'!W12+'DG M&A-SPA_POSN'!R12 -> 21081600 | P17: =+R17 -> 0 | V17: =+'DG M&A-SPA_POSN'!BM12 -> 13632000 | X17: =+J17+M17+P17+V17=G17*F17 -> 1
D18: POS-3 | F18: 400000 | G18: =+'DG M&A-SPA_POSN'!D17 -> 144.84 | H18: =+F18*G18/1470 -> 39412.245 | I18: =+J18+M18+P18 -> 52142400 | J18: =+'DG M&A-SPA_POSN'!Q18 -> 39513600 | M18: =+O18 -> 12628800 | N18: =+'DG M&A-SPA_POSN'!AA23 -> 45960 | O18: =+'DG M&A-SPA_POSN'!W18+'DG M&A-SPA_POSN'!R18 -> 12628800 | P18: =+R18 -> 0 | V18: =+'DG M&A-SPA_POSN'!BM18 -> 5793600 | X18: =+J18+M18+P18+V18=G18*F18 -> 1
D19: POS-4 | F19: 400000 | G19: =+'DG M&A-SPA_POSN'!D23 -> 807.98 | H19: =+F19*G19/1470 -> 219858.5 | I19: =+J19+M19+P19 -> 290872800 | J19: =+'DG M&A-SPA_POSN'!Q24 -> 221382000 | M19: =+O19 -> 69490800 | N19: =+'DG M&A-SPA_POSN'!AA29 -> 45960 | O19: =+'DG M&A-SPA_POSN'!W24+'DG M&A-SPA_POSN'!R24 -> 69490800 | P19: =+R19 -> 0 | V19: =+'DG M&A-SPA_POSN'!BM24 -> 32319200 | X19: =+J19+M19+P19+V19=G19*F19 -> 1
D20: POS-8 | F20: 400000 | G20: =+'DG M&A-SPA_POSN'!D29 -> 249.92 | H20: =+F20*G20/1470 -> 68005.442 | I20: =+J20+M20+P20 -> 89971200 | J20: =+'DG M&A-SPA_POSN'!Q30 -> 69678000 | M20: =+O20 -> 20293200 | N20: =+'DG M&A-SPA_POSN'!AA35 -> 45950 | O20: =+'DG M&A-SPA_POSN'!W30+'DG M&A-SPA_POSN'!R30 -> 20293200 | P20: =+R20 -> 0 | V20: =+'DG M&A-SPA_POSN'!BM30 -> 9996800 | X20: =+J20+M20+P20+V20=G20*F20 -> 1
D21: Total | G21: =SUM(G17:G20) -> 1543.54 | H21: =SUM(H17:H20) -> 420010.88 | I21: =I22/1470 -> 378009.8 | J21: =J22/1470 -> 294000 | M21: =M22/1470 -> 84009.796 | O21: =O22/1470 -> 84009.796 | P21: =P22/1470 -> 0 | R21: =R22/1470 -> 0 | T21: =T22/1470 -> 0 | V21: =V22/1470 -> 42001.088
I22: =+SUM(I17:I20) -> 555674400 | J22: =+SUM(J17:J20) -> 432180000 | M22: =+SUM(M17:M20) -> 123494400 | O22: =+SUM(O17:O20) -> 123494400 | P22: =+SUM(P17:P20) -> 0 | R22: =+SUM(R17:R20) -> 0 | T22: =+SUM(T17:T20) -> 0 | V22: =+SUM(V17:V20) -> 61741600
B23: Total | G23: =+G15 -> 1543.54 | H23: =+H15+H21 -> 1690543.8 | I23: =I24/1470 -> 1013276.3 | J23: =J24/1470 -> 294000 | K23: =K24/1470 -> 3489.8435 | L23: =L24/1470 -> 841509.91 | M23: =M24/1470 -> 719276.26 | O23: =O24/1470 -> 719276.26 | P23: =P24/1470 -> 0 | R23: =R24/1470 -> 0 | T23: =T24/1470 -> 0 | V23: =V24/1470 -> 677267.55
I24: =+I16+I22 -> 1489516100 | J24: =+J16+J22 -> 432180000 | K24: 5130070 | L24: =+D33+M22-K24 -> 1237019573 | M24: =+M16+M22 -> 1057336100 | O24: =+O16+O22 -> 1057336100 | P24: =+P16 -> 0 | R24: =+R16 -> 0 | T24: =+T16 -> 0 | V24: =+V16+V22 -> 995583300
B26: ※ CAPEX amount to be paid on 15 Oct. | P26: =+G19 -> 807.98
B27: Category | C27: Amount | D27: 45931 | F27: 46022 | H27: Remark | K27: 818246865
B28: CAPEX | C28: =+H15*1470 -> 1867683400 | D28: =+C28*50% -> 933841700 | E28: =+D28/1470 -> 635266.46 | F28: =+C28*50% -> 933841700 | G28: =+F28/1470 -> 635266.46 | J28: =+G11/$G$15 -> 0.22079117 | K28: =+J28*$K$27 -> 1.8066168e+08 | L28: 내일
B29: Grid Connection Fee | C29: -46492230 | D29: =+C29*100% -> -46492230 | E29: =+D29/1470 -> -31627.367 | G29: =+F29/1470 -> 0 | H29: Paid in advance on 12 Sep. | J29: =+G12/$G$15 -> 0.093836247 | K29: =+J29*$K$27 -> 76781215 | L29: 포스엔 하고 2호 돈이 얼마가 들어왔고
B30: Additional CAPEX Cost | C30: 44000000 | D30: =+C30 -> 44000000 | E30: =+D30/1470 -> 29931.973 | G30: =+F30/1470 -> 0 | H30: Reflected in the Oct. billing amount | J30: =+G13/$G$15 -> 0.52345906 | K30: =+J30*$K$27 -> 4.2831874e+08 | L30: 나가야 되는 돈 | M30: 나가야 되는 돈
B31: Prepaid Lease Fee | C31: 182895773 | D31: =+C31 -> 182895773 | E31: =+D31/1470 -> 124418.89 | G31: =+F31/1470 -> 0 | H31: Remaining lease fees for 5 years prepaid for POS_1, 3, 4, and 8 | J31: =+G14/$G$15 -> 0.16191352 | K31: =+J31*$K$27 -> 1.3248523e+08 | L31: 임대료 | M31: 2에서 나가야 되는 돈
B32: OE Fee | C32: 4410000 | D32: =+C32 -> 4410000 | E32: =+D32/1470 -> 3000 | G32: =+F32/1470 -> 0 | L32: CAPEX | M32: 이렇게 이렇게 나갈거다…. 도영이사가 마테오 한테 메일 보내라…. 익일.
B33: Total | C33: =+SUM(C28:C32) -> 2052496943 | D33: =+SUM(D28:D32) -> 1118655243 | E33: =+SUM(E28:E32) -> 760989.96 | F33: =+SUM(F28:F32) -> 933841700 | G33: =+SUM(G28:G32) -> 635266.46
D34: Total | E34: =+E33+G33 -> 1396256.4 | F34: =1300464.9+124418.89+3000 -> 1427883.8 | G34: =1300464.9+124418.89 -> 1424883.8
I35: =+F35/H35 -> #DIV/0!
B36: 지급현황 | E36: =+E37/F37 -> 0.73113249 | F36: =+E37+220000000 -> 818246865
B37: 45975 | C37: 공사비 50% | E37: 598246865 | F37: 818246865
B38: 지급 내역
B39: 효성에너지팜 지급금액
B40: CAPEX 50%
B41: 계통연계비1
B42: 계통연계비2
...

Sheet Amount to be paid in 2025(Total
B2: SPV Name | D2: Bolt Taeyanggwang 1HO
B3: Business License Number | D3: 388-86-03459
B4: Corporate Registry Number | D4: 110111-9077515
B5: SPV Address | D5: #214, 42, Eonju-ro 147-gil, Gangnam-gu, Seoul, Korea
B6: Project Tech. | D6: GM_Batch1,2, DG_M&A
B7: Bank & Bank account Number | D7: KB Bank : 096301-04-103314
T8: [Unit : KRW, EUR / 1EUR=1,470KRW]
B9: SPV | C9: Batch | D9: Name of Project | E9: CAPEX per kWp | F9: Capacity (kWp) | G9: Total amount to be settled | H9: Total | I9: Paid (By Aug. 31, 2025) | J9: Balance on Aug. 20, 2025 | K9: Amount scheduled to be paid in Aug. to Sep. (2nd Drawdown Amount) | L9: Sep. | N9: Oct. | P9: Amount scheduled to be paid in Oct. to After Oct. (3rd Drawdown Amount) | Q9: Nov. | S9: After Nov. | V9: Review
L10: Date | M10: Payment | N10: Date | O10: Payment | Q10: Date | R10: Payment
B11: Bolt Taeyanggwang 1HO | C11: GM_Batch1 | D11: =+'GM Batch1'!C11 -> YJ NANSAN 1 | E11: 1050000 | F11: =+'GM Batch1'!D11 -> 999.58 | G11: =E11*F11*1.1/1470 -> 785384.29 | H11: =+I11+K11+P11 -> 0 | K11: =+M11+O11 -> 0 | P11: =+R11+T11 -> 0
D12: =+'GM Batch1'!C17 -> YJ NANSAN 2 | E12: 1050000 | F12: =+'GM Batch1'!D17 -> 999.58 | G12: =E12*F12*1.1/1470 -> 785384.29 | H12: =+I12+K12+P12 -> 0 | K12: =+M12+O12 -> 0 | P12: =+R12+T12 -> 0 | V12: =+I12+K12+P12=E12*F12*1.1 -> 0 | W12: =+E12*F12*1.1=I12+M12+O12+R12+T12 -> 0
D13: =+'GM Batch1'!C23 -> YJ GASI 1 | E13: 1050000 | F13: =+'GM Batch1'!D23 -> 999.6 | G13: =E13*F13*1.1/1470 -> 785400 | H13: =+I13+K13+P13 -> 0 | K13: =+M13+O13 -> 0 | P13: =+R13+T13 -> 0 | V13: =+I13+K13+P13=E13*F13*1.1 -> FALSE | W13: =+E13*F13*1.1=I13+M13+O13+R13+T13 -> 0
D14: =+'GM Batch1'!C29 -> YJ GASI 2 | E14: 1050000 | F14: =+'GM Batch1'!D29 -> 999.6 | G14: =E14*F14*1.1/1470 -> 785400 | H14: =+I14+K14+P14 -> 0 | K14: =+M14+O14 -> 0 | P14: =+R14+T14 -> 0 | V14: =+I14+K14+P14=E14*F14*1.1 -> FALSE | W14: =+E14*F14*1.1=I14+M14+O14+R14+T14 -> 0
D15: =+'GM Batch1'!C35 -> Dream 1 | E15: 1050000 | F15: =+'GM Batch1'!D35 -> 999.24 | G15: =E15*F15*1.1/1470 -> 785117.14 | H15: =+I15+K15+P15 -> 0 | K15: =+M15+O15 -> 0 | P15: =+R15+T15 -> 0 | V15: =+I15+K15+P15=E15*F15*1.1 -> FALSE | W15: =+E15*F15*1.1=I15+M15+O15+R15+T15 -> 0
D16: =+'GM Batch1'!C41 -> Dream 2 | E16: 1050000 | F16: =+'GM Batch1'!D41 -> 999.24 | G16: =E16*F16*1.1/1470 -> 785117.14 | H16: =+I16+K16+P16 -> 0 | K16: =+M16+O16 -> 0 | P16: =+R16+T16 -> 0 | V16: =+I16+K16+P16=E16*F16*1.1 -> FALSE | W16: =+E16*F16*1.1=I16+M16+O16+R16+T16 -> 0
D17: =+'GM Batch1'!C47 -> JEIL TECH 1 | E17: 1050000 | F17: =+'GM Batch1'!D47 -> 999.44 | G17: =E17*F17*1.1/1470 -> 785274.29 | H17: =+I17+K17+P17 -> 0 | K17: =+M17+O17 -> 0 | P17: =+R17+T17 -> 0 | V17: =+I17+K17+P17=E17*F17*1.1 -> FALSE | W17: =+E17*F17*1.1=I17+M17+O17+R17+T17 -> 0
D18: =+'GM Batch1'!C53 -> JEIL TECH 2 | E18: 1050000 | F18: =+'GM Batch1'!D53 -> 999.44 | G18: =E18*F18*1.1/1470 -> 785274.29 | H18: =+I18+K18+P18 -> 0 | K18: =+M18+O18 -> 0 | P18: =+R18+T18 -> 0 | V18: =+I18+K18+P18=E18*F18*1.1 -> 0 | W18: =+E18*F18*1.1=I18+M18+O18+R18+T18 -> 0
D19: Total | F19: =SUM(F11:F18) -> 7995.72 | G19: =SUM(G11:G18) -> 6282351.4 | I19: =I20/1470 -> 0 | K19: =K20/1470 -> 0 | M19: =M20/1470 -> 0 | O19: =O20/1470 -> 0 | P19: =P20/1470 -> 0 | R19: =R20/1470 -> 0 | T19: =T20/1470 -> 0
H20: =+SUM(H11:H18) -> 0 | I20: =+SUM(I11:I18) -> 0 | K20: =+SUM(K11:K18) -> 0 | M20: =+SUM(M11:M18) -> 0 | O20: =+SUM(O11:O18) -> 0 | P20: =+SUM(P11:P18) -> 0 | R20: =+SUM(R11:R18) -> 0 | T20: =+SUM(T11:T18) -> 0
C21: GM_Batch2 APA | D21: =+'GM Batch2-APA'!C11 -> Jangchon 1 (APA) | E21: 1050000 | F21: =+'GM Batch2-APA'!D11 -> 551.04 | G21: =E21*F21*1.1/1470 -> 432960 | H21: =+I21+K21+P21 -> 0 | K21: =+M21+O21 -> 0 | P21: =+R21+T21 -> 0 | V21: =+I21+K21+P21=E21*F21*1.1 -> 0 | W21: =+E21*F21*1.1=I21+M21+O21+R21+T21 -> 0
D22: =+'GM Batch2-APA'!C17 -> Soltop Masan 1 (APA) | E22: 1050000 | F22: =+'GM Batch2-APA'!D17 -> 399.04 | G22: =E22*F22*1.1/1470 -> 313531.43 | H22: =+I22+K22+P22 -> 0 | K22: =+M22+O22 -> 0 | P22: =+R22+T22 -> 0 | V22: =+I22+K22+P22=E22*F22*1.1 -> 0 | W22: =+E22*F22*1.1=I22+M22+O22+R22+T22 -> 0
D23: =+'GM Batch2-APA'!C23 -> Hanil Mugok 15 (APA) | E23: 1050000 | F23: =+'GM Batch2-APA'!D23 -> 499.96 | G23: =E23*F23*1.1/1470 -> 392825.71 | H23: =+I23+K23+P23 -> 0 | K23: =+M23+O23 -> 0 | P23: =+R23+T23 -> 0 | V23: =+I23+K23+P23=E23*F23*1.1 -> 0 | W23: =+E23*F23*1.1=I23+M23+O23+R23+T23 -> 0
D24: =+'GM Batch2-APA'!C29 -> Hanil Jigyeong 1 (APA) | E24: 1050000 | F24: =+'GM Batch2-APA'!D29 -> 499.96 | G24: =E24*F24*1.1/1470 -> 392825.71 | H24: =+I24+K24+P24 -> 0 | K24: =+M24+O24 -> 0 | P24: =+R24+T24 -> 0 | V24: =+I24+K24+P24=E24*F24*1.1 -> 0 | W24: =+E24*F24*1.1=I24+M24+O24+R24+T24 -> 0
D25: =+'GM Batch2-APA'!C35 -> Hanil Jigyeong 2 (APA) | E25: 1050000 | F25: =+'GM Batch2-APA'!D35 -> 149.64 | G25: =E25*F25*1.1/1470 -> 117574.29 | H25: =+I25+K25+P25 -> 0 | K25: =+M25+O25 -> 0 | P25: =+R25+T25 -> 0 | V25: =+I25+K25+P25=E25*F25*1.1 -> 0 | W25: =+E25*F25*1.1=I25+M25+O25+R25+T25 -> 0
D26: =+'GM Batch2-APA'!C41 -> Ho Duck4 (APA) | E26: 1050000 | F26: =+'GM Batch2-APA'!D41 -> 299.28 | G26: =E26*F26*1.1/1470 -> 235148.57 | H26: =+I26+K26+P26 -> 0 | K26: =+M26+O26 -> 0 | P26: =+R26+T26 -> 0 | V26: =+I26+K26+P26=E26*F26*1.1 -> 0 | W26: =+E26*F26*1.1=I26+M26+O26+R26+T26 -> 0
D27: Total | F27: =SUM(F21:F26) -> 2398.92 | G27: =SUM(G21:G26) -> 1884865.7 | I27: =I28/1470 -> 0 | K27: =K28/1470 -> 0 | M27: =M28/1470 -> 0 | O27: =O28/1470 -> 0 | P27: =P28/1470 -> 0 | R27: =R28/1470 -> 0 | T27: =T28/1470 -> 0
H28: =+SUM(H21:H26) -> 0 | I28: =+SUM(I21:I26) -> 0 | K28: =+SUM(K21:K26) -> 0 | M28: =+SUM(M21:M26) -> 0 | O28: =+SUM(O21:O26) -> 0 | P28: =+SUM(P21:P26) -> 0 | R28: =+SUM(R21:R26) -> 0 | T28: =+SUM(T21:T26) -> 0 | V28: =+#REF!=H28 -> #REF!
C29: GM_Batch2 SPA | D29: =+'GM Batch2-SPA'!C11 -> Galsan (SPA) | E29: 1050000 | F29: =+'GM Batch2-SPA'!D11 -> 993.6 | G29: =E29*F29*1.1/1470 -> 780685.71 | H29: =+I29+K29+P29 -> 0 | K29: =+M29+O29 -> 0 | P29: =+R29+T29 -> 0 | V29: =+I29+K29+P29=E29*F29*1.1 -> 0 | W29: =+E29*F29*1.1=I29+M29+O29+R29+T29 -> 0
D30: =+'GM Batch2-SPA'!C17 -> Mineuri (SPA) | E30: 1050000 | F30: =+'GM Batch2-SPA'!D17 -> 993.6 | G30: =E30*F30*1.1/1470 -> 780685.71 | H30: =+I30+K30+P30 -> 0 | K30: =+M30+O30 -> 0 | P30: =+R30+T30 -> 0 | V30: =+I30+K30+P30=E30*F30*1.1 -> 0 | W30: =+E30*F30*1.1=I30+M30+O30+R30+T30 -> 0
D31: =+'GM Batch2-SPA'!C23 -> Seagol(SPA) | E31: 1050000 | F31: =+'GM Batch2-SPA'!D23 -> 993.6 | G31: =E31*F31*1.1/1470 -> 780685.71 | H31: =+I31+K31+P31 -> 0 | K31: =+M31+O31 -> 0 | P31: =+R31+T31 -> 0 | V31: =+I31+K31+P31=E31*F31*1.1 -> 0 | W31: =+E31*F31*1.1=I31+M31+O31+R31+T31 -> 0
D32: =+'GM Batch2-SPA'!C29 -> Jaesan (SPA) | E32: 1050000 | F32: =+'GM Batch2-SPA'!D29 -> 993.6 | G32: =E32*F32*1.1/1470 -> 780685.71 | H32: =+I32+K32+P32 -> 0 | K32: =+M32+O32 -> 0 | P32: =+R32+T32 -> 0 | V32: =+I32+K32+P32=E32*F32*1.1 -> 0 | W32: =+E32*F32*1.1=I32+M32+O32+R32+T32 -> 0
D33: Total | F33: =SUM(F29:F32) -> 3974.4 | G33: =SUM(G29:G32) -> 3122742.9 | I33: =I34/1470 -> 0 | K33: =K34/1470 -> 0 | M33: =M34/1470 -> 0 | O33: =O34/1470 -> 0 | P33: =P34/1470 -> 0 | R33: =R34/1470 -> 0 | T33: =T34/1470 -> 0
H34: =+SUM(H29:H32) -> 0 | I34: =+SUM(I29:I32) -> 0 | K34: =+SUM(K29:K32) -> 0 | M34: =+SUM(M29:M32) -> 0 | O34: =+SUM(O29:O32) -> 0 | P34: =+SUM(P29:P32) -> 0 | R34: =+SUM(R29:R32) -> 0 | T34: =+SUM(T29:T32) -> 0 | V34: =+#REF!=H34 -> #REF!
C35: DG_M&A_SPA_POSN | D35: =+'DG M&A-SPA_POSN'!C11 -> POS-1 | E35: =+'PAYMENT RATIO_RAW'!BK53/1000 -> 1125915.1 | F35: =+'DG M&A-SPA_POSN'!D11 -> 340.8 | G35: =E35*F35*1.1/1470 -> 287131.34 | H35: =+I35+K35+P35 -> 0 | K35: =+M35+O35 -> 0 | P35: =+R35+T35 -> 0 | V35: =+I35+K35+P35=E35*F35*1.1 -> 0 | W35: =+E35*F35*1.1=I35+M35+O35+R35+T35 -> 0
D36: =+'DG M&A-SPA_POSN'!C17 -> POS-3 | E36: =+'PAYMENT RATIO_RAW'!BK54/1000 -> 1125915.1 | F36: =+'DG M&A-SPA_POSN'!D17 -> 144.84 | G36: =E36*F36*1.1/1470 -> 122030.82 | H36: =+I36+K36+P36 -> 0 | K36: =+M36+O36 -> 0 | P36: =+R36+T36 -> 0 | V36: =+I36+K36+P36=E36*F36*1.1 -> 0
D37: =+'DG M&A-SPA_POSN'!C23 -> POS-4 | E37: =+'PAYMENT RATIO_RAW'!BK55/1000 -> 1125915.1 | F37: =+'DG M&A-SPA_POSN'!D23 -> 807.98 | G37: =E37*F37*1.1/1470 -> 680740.54 | H37: =+I37+K37+P37 -> 0 | K37: =+M37+O37 -> 0 | P37: =+R37+T37 -> 0 | V37: =+I37+K37+P37=E37*F37*1.1 -> 0
D38: =+'DG M&A-SPA_POSN'!C29 -> POS-8 | E38: =+'PAYMENT RATIO_RAW'!BK56/1000 -> 1125915.1 | F38: =+'DG M&A-SPA_POSN'!D29 -> 249.92 | G38: =E38*F38*1.1/1470 -> 210562.98 | H38: =+I38+K38+P38 -> 0 | K38: =+M38+O38 -> 0 | P38: =+R38+T38 -> 0 | V38: =+I38+K38+P38=E38*F38*1.1 -> 0 | W38: =+E38*F38*1.1=I38+M38+O38+R38+T38 -> 0
D39: Total | F39: =+SUM(F35:F38) -> 1543.54 | G39: =+SUM(G35:G38) -> 1300465.7 | H39: =H40/1470 -> 0 | I39: =I40/1470 -> 0 | J39: =J40/1470 -> 378254.36 | K39: =K40/1470 -> 0 | M39: =M40/1470 -> 0 | O39: =O40/1470 -> 0 | P39: =P40/1470 -> 0 | R39: =R40/1470 -> 0 | T39: =T40/1470 -> 0
H40: =+SUM(H35:H38) -> 0 | I40: =+SUM(I35:I38) -> 0 | J40: =+Summary!E7 -> 5.5603391e+08 | K40: =+SUM(K35:K38) -> 0 | M40: =+SUM(M35:M38) -> 0 | O40: =+SUM(O35:O38) -> 0 | P40: =+SUM(P35:P38) -> 0 | R40: =+SUM(R35:R38) -> 0 | T40: =+SUM(T35:T38) -> 0 | V40: =+#REF!=H40 -> #REF!
C41: GM_Batch1,2 | F41: =+F19+F27+F33 -> 14369.04 | G41: =+G33+G27+G19 -> 11289960 | H41: =H42/1470 -> 0 | I41: =I42/1470 -> 0 | J41: =J42/1470 -> 0 | K41: =K42/1470 -> 0 | M41: =M42/1470 -> 0 | O41: =O42/1470 -> 0 | P41: =P42/1470 -> 0 | R41: =R42/1470 -> 0 | T41: =T42/1470 -> 0
...

Sheet INPUTSHEET(Batch2)
A1: Input sheet for financial modelling purpose
E2: Project 1 | F2: Project 2 | G2: Project 3 | H2: Project 4 | I2: Project 5 | J2: Project 6 | K2: Project 7 | L2: Project 8 | M2: Project 9 | N2: Project 10 | O2: Project 10 | R2: Project 1 | S2: Project 2 | T2: Project 3 | U2: Project 4 | V2: Project 5 | W2: Project 6
B3: General inputs
N4: [Unit: KRW]
B5: Seller/developer name | C5: name | E5: Ssoltop Miracle Inc. | F5: Ssoltop Masan 1 Solar | G5: Mugok Inc. | H5: Jigyeong Inc. | I5: Seongsi 3 Solar | J5: Hoduck 4 Solar | K5: Galsan Solar | L5: Mineuri Solar | M5: Saegol Solar | N5: Jaesan Solar | R5: =+'[3]BT 2HO'!R11 -> 0 | S5: =+'[3]BT 2HO'!R16 -> 0 | T5: =+'[3]BT 2HO'!R21 -> 0 | U5: =+'[3]BT 2HO'!R26 -> 0 | V5: =+'[3]BT 2HO'!R31 -> 0 | W5: =+'[3]BT 2HO'!R41 -> 0
B6: Project name | C6: name | E6: Jangchon 1 | F6: Soltop Masan 1 | G6: Hanil Mugok 15 | H6: Hanil Jigyeong 1 | I6: Hanil Jigyeong 2 | J6: Ho Duck4 | K6: Galsan Solar | L6: Mineuri Solar | M6: Saegol Solar | N6: Jaesan Solar | R6: =+R5 -> 0 | S6: =+S5 -> 0 | T6: =+T5 -> 0 | U6: =+U5 -> 0 | V6: =+V5 -> 0 | W6: =+W5 -> 0
B7: Country | C7: Please select -- | E7: Korea | F7: Korea | G7: Korea | H7: Korea | I7: Korea | J7: Korea | K7: Korea | L7: Korea | M7: Korea | N7: Korea | O7: Korea | R7: Korea | S7: Korea | T7: Korea | U7: Korea | V7: Korea | W7: Korea
B8: Region | C8: Please specify the location of the plant | E8: Haenam-gun, Jeollanam-do | F8: Youngdong-gun, Chungcheongbuk-do | G8: Hapcheon-gun, Gyeongsangnam-do | H8: Youngyang-gun, Gyeongsangbuk-do | I8: Youngyang-gun, Gyeongsangbuk-do | J8: Goheung-gun, Jeollanam-do | K8: Bonghwa-gun, Gyeongsangbuk-do | L8: Bonghwa-gun, Gyeongsangbuk-do | M8: Bonghwa-gun, Gyeongsangbuk-do | N8: Bonghwa-gun, Gyeongsangbuk-do | R8: Busan | S8: Busan | T8: Chungcheongbuk-do | U8: Gyeonggi-do | V8: Gyeonggi-do | W8: Gyeonggi-do
B9: Technology | C9: Please select -- | E9: PV | F9: PV | G9: PV | H9: PV | I9: PV | J9: PV | K9: PV | L9: PV | M9: PV | N9: PV | O9: PV | R9: PV | S9: PV | T9: PV | U9: PV | V9: PV | W9: PV
B10: Project Status | C10: Please select -- | E10: =+'[4]입력 시트(0124)'!E10 -> RTB | F10: =+'[4]입력 시트(0124)'!F10 -> RTB | G10: =+'[4]입력 시트(0124)'!G10 -> RTB | H10: =+'[4]입력 시트(0124)'!H10 -> RTB | I10: =+'[4]입력 시트(0124)'!I10 -> RTB | J10: =+'[4]입력 시트(0124)'!J10 -> RTB | K10: =+'[4]입력 시트(0124)'!K10 -> RTB | L10: =+'[4]입력 시트(0124)'!L10 -> RTB | ... N10: =+'[4]입력 시트(0124)'!N10 -> RTB | O10: EBL | R10: RtB | S10: RtB | T10: RtB | U10: RtB | V10: RtB | W10: EBL
B11: Transaction structure | C11: Please provide background on the deal | E11: Ground | F11: Ground | G11: Ground | H11: Ground | I11: Ground | J11: Ground | K11: Ground | L11: Ground | M11: Ground | N11: Ground | O11: ROOFTOP | R11: ROOFTOP | S11: ROOFTOP | T11: ROOFTOP | U11: ROOFTOP | V11: ROOFTOP | W11: ROOFTOP
B12: Input source | C12: Please specify if this input list is based on internal assumptions or seller assumptions. | E12: Internal assumptions | F12: Internal assumptions | G12: Internal assumptions | H12: Internal assumptions | I12: Internal assumptions | J12: Internal assumptions | K12: Internal assumptions | L12: Internal assumptions | M12: Internal assumptions | N12: Internal assumptions | O12: Internal assumptions | R12: Internal assumptions | S12: Internal assumptions | T12: Internal assumptions | U12: Internal assumptions | V12: Internal assumptions | W12: Internal assumptions
B14: Currency | C14: Please select currency for financial modelling purposes -- | E14: KRW | F14: KRW | G14: KRW | H14: KRW | I14: KRW | J14: KRW | K14: KRW | L14: KRW | M14: KRW | N14: KRW | O14: KRW | R14: KRW | S14: KRW | T14: KRW | U14: KRW | V14: KRW | W14: KRW
B16: RTB date | C16: date (day/month/year) | E16: 46143 | F16: 46143 | G16: 46143 | H16: 46143 | I16: 46143 | J16: 46143 | K16: 46266 | L16: 46266 | M16: 46266 | N16: 46266 | O16: 46022 | R16: 45962 | S16: 45962 | T16: 45962 | U16: 45962 | V16: 45962 | W16: 46022
B17: Construction phase | C17: Months | E17: 5 | F17: 5 | G17: 5 | H17: 5 | I17: 5 | J17: 5 | K17: 5 | L17: 5 | M17: 5 | N17: 5 | O17: 5 | R17: 5 | S17: 5 | T17: 5 | U17: 5 | V17: 5 | W17: 5
B18: SOC date | E18: =+EDATE(E16,2) -> 46204 | F18: =+EDATE(F16,2) -> 46204 | G18: =+EDATE(G16,2) -> 46204 | H18: =+EDATE(H16,2) -> 46204 | I18: =+EDATE(I16,2) -> 46204 | J18: =+EDATE(J16,2) -> 46204 | K18: =+EDATE(K16,2) -> 46327 | L18: =+EDATE(L16,2) -> 46327 | ... N18: =+EDATE(N16,2) -> 46327 | R18: 46053 | S18: 46022 | T18: 46022 | U18: 46022 | V18: 46022 | W18: 46053
B19: COD date | C19: date (day/month/year) | E19: =+EDATE(E16,5) -> 46296 | F19: =+EDATE(F16,5) -> 46296 | G19: =+EDATE(G16,5) -> 46296 | H19: =+EDATE(H16,5) -> 46296 | I19: =+EDATE(I16,5) -> 46296 | J19: =+EDATE(J16,5) -> 46296 | K19: =+EDATE(K16,5) -> 46419 | L19: =+EDATE(L16,5) -> 46419 | ... N19: =+EDATE(N16,5) -> 46419 | O19: 46203 | R19: 46203 | S19: 46173 | T19: 46173 | U19: 46173 | V19: 46173 | W19: 46203
B20: Asset Useful Life | C20: years | D20: Default will be 20 years | E20: 35 | F20: 35 | G20: 35 | H20: 35 | I20: 35 | J20: 35 | K20: 35 | L20: 35 | M20: 35 | N20: 35 | O20: 20 | R20: 20 | S20: 20 | T20: 20 | U20: 20 | V20: 20 | W20: 20
B22: WTG / Panels number | C22: If PV in E9 please put N/A | E22: N/A | F22: N/A | G22: N/A | H22: N/A | I22: N/A | J22: N/A | K22: N/A | L22: N/A | M22: N/A | N22: N/A | O22: N/A | R22: N/A | S22: N/A | T22: N/A | U22: N/A | V22: N/A | W22: N/A
B23: WTG / Panels name | C23: If PV in E9 please put N/A | E23: N/A | F23: N/A | G23: N/A | H23: N/A | I23: N/A | J23: N/A | K23: N/A | L23: N/A | M23: N/A | N23: N/A | O23: N/A | R23: N/A | S23: N/A | T23: N/A | U23: N/A | V23: N/A | W23: N/A
B24: Total Capacity DC | C24: MWp | E24: =+#REF!/1000 -> #REF! | F24: =+#REF!/1000 -> #REF! | G24: =+#REF!/1000 -> #REF! | H24: =+#REF!/1000 -> #REF! | I24: =+#REF!/1000 -> #REF! | J24: =+#REF!/1000 -> #REF! | K24: =+#REF!/1000 -> #REF! | L24: =+#REF!/1000 -> #REF! | ... N24: =+#REF!/1000 -> #REF! | R24: =+'[3]CAPEX_Input_3,7HO(수정용)'!T40 -> 0.084744677 | S24: =+'[3]CAPEX_Input_3,7HO(수정용)'!T33 -> 0.024285621 | T24: =+'[3]CAPEX_Input_3,7HO(수정용)'!T34 -> 0.036847296 | U24: =+'[3]CAPEX_Input_3,7HO(수정용)'!T35 -> 0.019635 | V24: =+'[3]CAPEX_Input_3,7HO(수정용)'!T37 -> 0.0112118 | W24: =+'[3]CAPEX_Input_3,7HO(수정용)'!T41 -> 0.0423984
B25: Total Capacity AC | C25: Mwac . If Wind in E9 please put N/A
B26: DC/AC ratio | C26: If Wind in E9 please put N/A | E26: =+E24/E25 -> #REF! | F26: =+F24/F25 -> #REF! | G26: =+G24/G25 -> #REF! | H26: =+H24/H25 -> #REF! | I26: =+I24/I25 -> #REF! | J26: =+J24/J25 -> #REF! | K26: =+K24/K25 -> #REF! | L26: =+L24/L25 -> #REF! | ... O26: =+O24/O25 -> #DIV/0! | R26: =+R24/R25 -> #DIV/0! | S26: =+S24/S25 -> #DIV/0! | T26: =+T24/T25 -> #DIV/0! | U26: =+U24/U25 -> #DIV/0! | V26: =+V24/V25 -> #DIV/0! | W26: =+W24/W25 -> #DIV/0!
B28: Production
B30: Load Factor (After Curtailment)
B31: P50 | C31: %
B32: P75 | C32: %
B33: P90 | C33: %
B35: Number of Equivalent Hours (day)
B36: P50 | C36: Hours | E36: 3.5232877 | F36: 3.9013699 | G36: 3.9643836 | H36: 3.7917808 | I36: 3.7917808 | J36: 4.090411 | K36: 3.9726027 | L36: 3.9726027 | M36: 3.9671233 | N36: 3.9726027 | O36: =+'[3]CAPEX_Input_3,7HO(수정용)'!G44/365 -> 3.8630137 | R36: =+'[3]CAPEX_Input_3,7HO(수정용)'!V40/365 -> 0 | S36: =+'[3]CAPEX_Input_3,7HO(수정용)'!V33/365 -> 0 | T36: =+'[3]CAPEX_Input_3,7HO(수정용)'!V34/365 -> 0 | U36: =+'[3]CAPEX_Input_3,7HO(수정용)'!V35/365 -> 0 | V36: =+'[3]CAPEX_Input_3,7HO(수정용)'!V37/365 -> 0 | W36: =+'[3]CAPEX_Input_3,7HO(수정용)'!V41/365 -> 0
B37: P75 | C37: Hours
B38: P90 | C38: Hours
B40: Production
B41: P50 | C41: MWh | E41: =+E24*E36*365 -> #REF! | F41: =+F24*F36*365 -> #REF! | G41: =+G24*G36*365 -> #REF! | H41: =+H24*H36*365 -> #REF! | I41: =+I24*I36*365 -> #REF! | J41: =+J24*J36*365 -> #REF! | K41: =+K24*K36*365 -> #REF! | L41: =+L24*L36*365 -> #REF! | ... O41: =+O24*O36*365 -> 0 | R41: =+R24*R36*365 -> 0 | S41: =+S24*S36*365 -> 0 | T41: =+T24*T36*365 -> 0 | U41: =+U24*U36*365 -> 0 | V41: =+V24*V36*365 -> 0 | W41: =+W24*W36*365 -> 0
B42: P75 | C42: MWh
B43: Specific Production | C43: [kWh/kWp]
B45: Availability | C45: %
B47: Months before degradation | C47: %
B48: Start of degradation | C48: %
B49: Degradation Factor | C49: % | D49: Default will be 20 years | E49: 0.004 | F49: 0.004 | G49: 0.004 | H49: 0.004 | I49: 0.004 | J49: 0.004 | K49: 0.004 | L49: 0.004 | M49: 0.004 | N49: 0.004 | O49: 0.002 | R49: 0.002 | S49: 0.002 | T49: 0.002 | U49: 0.002 | V49: 0.002 | W49: 0.002
...

Sheet Amount to be paid_GM_Batch1
B2: SPV Name | D2: Bolt Taeyanggwang 1HO
B3: Business License Number | D3: 388-86-03459
B4: Corporate Registry Number | D4: 110111-9077515
B5: SPV Address | D5: #214, 42, Eonju-ro 147-gil, Gangnam-gu, Seoul, Korea
B6: Project Tech. | D6: GM_Batch1,2, DG_M&A
B7: Bank & Bank account Number | D7: KB Bank : 096368-11-010020
M8: 30% of CAPEX | O8: 40% of CAPEX | T8: [Unit : KRW, EUR / 1EUR=1,470KRW]
